Workbook

Sheet README
B2: TCO & Scenario Model: Aluminium Smartphone Enclosure, India vs China vs Vietnam
B3: Independent academic project built from public data and stated assumptions. Not Apple data.
B5: Question | C5: Where should a CNC-machined aluminium enclosure be sourced from to be delivered to a final-assembly plant near Chennai: a local Indian supplier, or imports from China or Vietnam? And how robust is the answer to tariff, freight, volume, metal-price, incentive and yield shocks?
B6: Part modelled | C6: Unibody-style CNC-machined 6xxx aluminium enclosure, 28 g finished, 85 g blank, anodised. Delivered cost to the assembly plant (Chennai area), USD per unit, at 5 million units per year per supplier line.
B7: Cost layers | C7: Net material (after chip-scrap credit) > machining > direct labour > finishing > yield loss > fixed cost per unit (tooling + overhead) > supplier margin > ECMS incentive (India only) > freight > insurance > Basic Customs Duty + Social Welfare Surcharge + other duties > clearance and haulage > pipeline carrying cost.
B8: Sheets | C8: Inputs (all assumptions) > Scenarios (11 shock definitions) > Calc (33-column engine, same formula in every column) > Summary (results, cost stack, charts) > Sensitivity (two-way grids and break-evens) > Incoterms (FOB vs CIF vs DDP, who pays what) > Sources (what is sourced vs assumed).
B9: How to use | C9: Change only BLUE cells on Inputs or Scenarios. Everything else recalculates. Yellow cells mark the key levers. To test your own idea, overwrite a scenario row on the Scenarios sheet.
B10: Colour code | C10: Blue = hard-coded input. Black = formula. Green = link to another sheet. Yellow fill = key assumption or lever.
B11: Important limitation | C11: Process inputs (cycle time, machine rate, labour rate, yield, tooling, freight rates) are illustrative values in plausible ranges, NOT quotes. Public anchors (LME price, ECMS incentive range, tariff regime) are listed on the Sources sheet. Replace the blue cells with RFQ or benchmark data before drawing real conclusions.
B12: Simplifications | C12: IGST/GST is excluded because it is creditable to a registered manufacturer. Scrapped parts are not credited with metal value (conservative). Anti-dumping duty is an input set to zero. Vietnam BCD of 5% is a placeholder for a possible ASEAN-India FTA preferential rate and must be verified against HS code and rules of origin. US tariffs on the finished device are discussed in the memo, not modelled here.

Sheet Summary
A1: Results: landed cost of an aluminium enclosure delivered near Chennai (USD per unit)
A2: All values are formulas driven by the Inputs and Scenarios sheets. Green cell = cheapest source in that scenario.
A4: Landed cost per unit by scenario | B4: Local | C4: Import | D4: Import
A5: Scenario | B5: =Inputs!$C$18 -> India | C5: =Inputs!$D$18 -> China | D5: =Inputs!$E$18 -> Vietnam | E5: Cheapest source | F5: India vs China (%) | G5: India vs Vietnam (%)
A6: =Scenarios!$A$5 -> Base case | B6: {=INDEX(Calc!$C$66:$AI$66,MATCH($A6&"|"&B$5,Calc!$C$6:$AI$6,0))} -> 4.0300006 | C6: {=INDEX(Calc!$C$66:$AI$66,MATCH($A6&"|"&C$5,Calc!$C$6:$AI$6,0))} -> 3.6772119 | D6: {=INDEX(Calc!$C$66:$AI$66,MATCH($A6&"|"&D$5,Calc!$C$6:$AI$6,0))} -> 3.9697692 | E6: =INDEX($B$5:$D$5,MATCH(MIN(B6:D6),B6:D6,0)) -> China | F6: =B6/C6-1 -> 0.095939197 | G6: =B6/D6-1 -> 0.015172521
A7: =Scenarios!$A$6 -> Import duty +10 pts | B7: {=INDEX(Calc!$C$66:$AI$66,MATCH($A7&"|"&B$5,Calc!$C$6:$AI$6,0))} -> 4.0300006 | C7: {=INDEX(Calc!$C$66:$AI$66,MATCH($A7&"|"&C$5,Calc!$C$6:$AI$6,0))} -> 4.0385565 | D7: {=INDEX(Calc!$C$66:$AI$66,MATCH($A7&"|"&D$5,Calc!$C$6:$AI$6,0))} -> 4.3804936 | E7: =INDEX($B$5:$D$5,MATCH(MIN(B7:D7),B7:D7,0)) -> India | F7: =B7/C7-1 -> -0.0021185508 | G7: =B7/D7-1 -> -0.080012213
A8: =Scenarios!$A$7 -> Import duty exempt (BCD to 0) | B8: {=INDEX(Calc!$C$66:$AI$66,MATCH($A8&"|"&B$5,Calc!$C$6:$AI$6,0))} -> 4.0300006 | C8: {=INDEX(Calc!$C$66:$AI$66,MATCH($A8&"|"&C$5,Calc!$C$6:$AI$6,0))} -> 3.3158672 | D8: {=INDEX(Calc!$C$66:$AI$66,MATCH($A8&"|"&D$5,Calc!$C$6:$AI$6,0))} -> 3.764407 | E8: =INDEX($B$5:$D$5,MATCH(MIN(B8:D8),B8:D8,0)) -> China | F8: =B8/C8-1 -> 0.21536851 | G8: =B8/D8-1 -> 0.070553901
A9: =Scenarios!$A$8 -> Freight spike x2.5 | B9: {=INDEX(Calc!$C$66:$AI$66,MATCH($A9&"|"&B$5,Calc!$C$6:$AI$6,0))} -> 4.0426006 | C9: {=INDEX(Calc!$C$66:$AI$66,MATCH($A9&"|"&C$5,Calc!$C$6:$AI$6,0))} -> 3.9053034 | D9: {=INDEX(Calc!$C$66:$AI$66,MATCH($A9&"|"&D$5,Calc!$C$6:$AI$6,0))} -> 4.219958 | E9: =INDEX($B$5:$D$5,MATCH(MIN(B9:D9),B9:D9,0)) -> China | F9: =B9/C9-1 -> 0.035156616 | G9: =B9/D9-1 -> -0.042028226
A10: =Scenarios!$A$9 -> Volume -10% | B10: {=INDEX(Calc!$C$66:$AI$66,MATCH($A10&"|"&B$5,Calc!$C$6:$AI$6,0))} -> 4.0721398 | C10: {=INDEX(Calc!$C$66:$AI$66,MATCH($A10&"|"&C$5,Calc!$C$6:$AI$6,0))} -> 3.7301651 | D10: {=INDEX(Calc!$C$66:$AI$66,MATCH($A10&"|"&D$5,Calc!$C$6:$AI$6,0))} -> 4.0119265 | E10: =INDEX($B$5:$D$5,MATCH(MIN(B10:D10),B10:D10,0)) -> China | F10: =B10/C10-1 -> 0.091678161 | G10: =B10/D10-1 -> 0.015008565
A11: =Scenarios!$A$10 -> Volume +10% | B11: {=INDEX(Calc!$C$66:$AI$66,MATCH($A11&"|"&B$5,Calc!$C$6:$AI$6,0))} -> 3.9955232 | C11: {=INDEX(Calc!$C$66:$AI$66,MATCH($A11&"|"&C$5,Calc!$C$6:$AI$6,0))} -> 3.6338865 | D11: {=INDEX(Calc!$C$66:$AI$66,MATCH($A11&"|"&D$5,Calc!$C$6:$AI$6,0))} -> 3.9352769 | E11: =INDEX($B$5:$D$5,MATCH(MIN(B11:D11),B11:D11,0)) -> China | F11: =B11/C11-1 -> 0.099517867 | G11: =B11/D11-1 -> 0.015309279
A12: =Scenarios!$A$11 -> Aluminium +15% | B12: {=INDEX(Calc!$C$66:$AI$66,MATCH($A12&"|"&B$5,Calc!$C$6:$AI$6,0))} -> 4.0592543 | C12: {=INDEX(Calc!$C$66:$AI$66,MATCH($A12&"|"&C$5,Calc!$C$6:$AI$6,0))} -> 3.7083251 | D12: {=INDEX(Calc!$C$66:$AI$66,MATCH($A12&"|"&D$5,Calc!$C$6:$AI$6,0))} -> 4.0005884 | E12: =INDEX($B$5:$D$5,MATCH(MIN(B12:D12),B12:D12,0)) -> China | F12: =B12/C12-1 -> 0.094632816 | G12: =B12/D12-1 -> 0.014664318
A13: =Scenarios!$A$12 -> ECMS delayed (0% pass-through) | B13: {=INDEX(Calc!$C$66:$AI$66,MATCH($A13&"|"&B$5,Calc!$C$6:$AI$6,0))} -> 4.1758618 | C13: {=INDEX(Calc!$C$66:$AI$66,MATCH($A13&"|"&C$5,Calc!$C$6:$AI$6,0))} -> 3.6772119 | D13: {=INDEX(Calc!$C$66:$AI$66,MATCH($A13&"|"&D$5,Calc!$C$6:$AI$6,0))} -> 3.9697692 | E13: =INDEX($B$5:$D$5,MATCH(MIN(B13:D13),B13:D13,0)) -> China | F13: =B13/C13-1 -> 0.13560543 | G13: =B13/D13-1 -> 0.051915503
A14: =Scenarios!$A$13 -> India yield -4 pts | B14: {=INDEX(Calc!$C$66:$AI$66,MATCH($A14&"|"&B$5,Calc!$C$6:$AI$6,0))} -> 4.2076762 | C14: {=INDEX(Calc!$C$66:$AI$66,MATCH($A14&"|"&C$5,Calc!$C$6:$AI$6,0))} -> 3.6772119 | D14: {=INDEX(Calc!$C$66:$AI$66,MATCH($A14&"|"&D$5,Calc!$C$6:$AI$6,0))} -> 3.9697692 | E14: =INDEX($B$5:$D$5,MATCH(MIN(B14:D14),B14:D14,0)) -> China | F14: =B14/C14-1 -> 0.1442572 | G14: =B14/D14-1 -> 0.059929665
A15: =Scenarios!$A$14 -> Import-shock stack (duty +10, freight x2.5, Al +15%) | B15: {=INDEX(Calc!$C$66:$AI$66,MATCH($A15&"|"&B$5,Calc!$C$6:$AI$6,0))} -> 4.0718543 | C15: {=INDEX(Calc!$C$66:$AI$66,MATCH($A15&"|"&C$5,Calc!$C$6:$AI$6,0))} -> 4.3233435 | D15: {=INDEX(Calc!$C$66:$AI$66,MATCH($A15&"|"&D$5,Calc!$C$6:$AI$6,0))} -> 4.6906801 | E15: =INDEX($B$5:$D$5,MATCH(MIN(B15:D15),B15:D15,0)) -> India | F15: =B15/C15-1 -> -0.058170062 | G15: =B15/D15-1 -> -0.13192666
A16: =Scenarios!$A$15 -> India-risk stack (vol -10%, ECMS 0%, yield -4 pts) | B16: {=INDEX(Calc!$C$66:$AI$66,MATCH($A16&"|"&B$5,Calc!$C$6:$AI$6,0))} -> 4.403649 | C16: {=INDEX(Calc!$C$66:$AI$66,MATCH($A16&"|"&C$5,Calc!$C$6:$AI$6,0))} -> 3.7301651 | D16: {=INDEX(Calc!$C$66:$AI$66,MATCH($A16&"|"&D$5,Calc!$C$6:$AI$6,0))} -> 4.0119265 | E16: =INDEX($B$5:$D$5,MATCH(MIN(B16:D16),B16:D16,0)) -> China | F16: =B16/C16-1 -> 0.1805507 | G16: =B16/D16-1 -> 0.097639503
A18: Base-case headline metrics
A19: Cheapest source (base case) | B19: =E6 -> China
A20: India local landed cost (USD/unit) | B20: =B6 -> 4.0300006
A21: China imported landed cost (USD/unit) | B21: =C6 -> 3.6772119
A22: India premium vs China (%) | B22: =F6 -> 0.095939197
A23: Break-even import duty (BCD) at which India local = China | B23: =Sensitivity!B26 -> 0.19763221
A24: Break-even freight multiplier at which India local = China | B24: =Sensitivity!B27 -> 3.3200476
A25: Annual spend gap, India minus China, at base volume (USD m) | B25: =(B6-C6)*Inputs!$B$10/1000000 -> 1.7639438
A26: Break-even India first-pass yield at which India local = China | B26: =Sensitivity!B48 -> 0.95223068
A28: Base-case cost stack (USD per unit)
A29: Component | B29: =Inputs!$C$18 -> India | C29: =Inputs!$D$18 -> China | D29: =Inputs!$E$18 -> Vietnam
A30: Net material | B30: {=INDEX(Calc!$C$41:$AI$41,MATCH(Summary!$A$6&"|"&B$29,Calc!$C$6:$AI$6,0))} -> 0.2034072 | C30: {=INDEX(Calc!$C$41:$AI$41,MATCH(Summary!$A$6&"|"&C$29,Calc!$C$6:$AI$6,0))} -> 0.1872572 | D30: {=INDEX(Calc!$C$41:$AI$41,MATCH(Summary!$A$6&"|"&D$29,Calc!$C$6:$AI$6,0))} -> 0.1974572
A31: Machining | B31: {=INDEX(Calc!$C$42:$AI$42,MATCH(Summary!$A$6&"|"&B$29,Calc!$C$6:$AI$6,0))} -> 2.1 | C31: {=INDEX(Calc!$C$42:$AI$42,MATCH(Summary!$A$6&"|"&C$29,Calc!$C$6:$AI$6,0))} -> 1.5333333 | D31: {=INDEX(Calc!$C$42:$AI$42,MATCH(Summary!$A$6&"|"&D$29,Calc!$C$6:$AI$6,0))} -> 1.8333333
A32: Direct labour | B32: {=INDEX(Calc!$C$43:$AI$43,MATCH(Summary!$A$6&"|"&B$29,Calc!$C$6:$AI$6,0))} -> 0.12 | C32: {=INDEX(Calc!$C$43:$AI$43,MATCH(Summary!$A$6&"|"&C$29,Calc!$C$6:$AI$6,0))} -> 0.21666667 | D32: {=INDEX(Calc!$C$43:$AI$43,MATCH(Summary!$A$6&"|"&D$29,Calc!$C$6:$AI$6,0))} -> 0.13933333
A33: Finishing | B33: {=INDEX(Calc!$C$44:$AI$44,MATCH(Summary!$A$6&"|"&B$29,Calc!$C$6:$AI$6,0))} -> 0.55 | C33: {=INDEX(Calc!$C$44:$AI$44,MATCH(Summary!$A$6&"|"&C$29,Calc!$C$6:$AI$6,0))} -> 0.4 | D33: {=INDEX(Calc!$C$44:$AI$44,MATCH(Summary!$A$6&"|"&D$29,Calc!$C$6:$AI$6,0))} -> 0.48
A34: Yield loss | B34: {=INDEX(Calc!$C$47:$AI$47,MATCH(Summary!$A$6&"|"&B$29,Calc!$C$6:$AI$6,0))} -> 0.48404303 | C34: {=INDEX(Calc!$C$47:$AI$47,MATCH(Summary!$A$6&"|"&C$29,Calc!$C$6:$AI$6,0))} -> 0.17592258 | D34: {=INDEX(Calc!$C$47:$AI$47,MATCH(Summary!$A$6&"|"&D$29,Calc!$C$6:$AI$6,0))} -> 0.29445821
A35: Fixed cost (tooling + overhead) | B35: {=INDEX(Calc!$C$48:$AI$48,MATCH(Summary!$A$6&"|"&B$29,Calc!$C$6:$AI$6,0))} -> 0.36 | C35: {=INDEX(Calc!$C$48:$AI$48,MATCH(Summary!$A$6&"|"&C$29,Calc!$C$6:$AI$6,0))} -> 0.39333333 | D35: {=INDEX(Calc!$C$48:$AI$48,MATCH(Summary!$A$6&"|"&D$29,Calc!$C$6:$AI$6,0))} -> 0.32666667
A36: Supplier margin | B36: {=INDEX(Calc!$C$50:$AI$50,MATCH(Summary!$A$6&"|"&B$29,Calc!$C$6:$AI$6,0))} -> 0.34357052 | C36: {=INDEX(Calc!$C$50:$AI$50,MATCH(Summary!$A$6&"|"&C$29,Calc!$C$6:$AI$6,0))} -> 0.23252105 | D36: {=INDEX(Calc!$C$50:$AI$50,MATCH(Summary!$A$6&"|"&D$29,Calc!$C$6:$AI$6,0))} -> 0.29441239
A37: ECMS incentive to buyer | B37: {=INDEX(Calc!$C$52:$AI$52,MATCH(Summary!$A$6&"|"&B$29,Calc!$C$6:$AI$6,0))} -> -0.14563573 | C37: {=INDEX(Calc!$C$52:$AI$52,MATCH(Summary!$A$6&"|"&C$29,Calc!$C$6:$AI$6,0))} -> 0 | D37: {=INDEX(Calc!$C$52:$AI$52,MATCH(Summary!$A$6&"|"&D$29,Calc!$C$6:$AI$6,0))} -> 0
A38: International freight | B38: {=INDEX(Calc!$C$56:$AI$56,MATCH(Summary!$A$6&"|"&B$29,Calc!$C$6:$AI$6,0))} -> 0.0084 | C38: {=INDEX(Calc!$C$56:$AI$56,MATCH(Summary!$A$6&"|"&C$29,Calc!$C$6:$AI$6,0))} -> 0.1365 | D38: {=INDEX(Calc!$C$56:$AI$56,MATCH(Summary!$A$6&"|"&D$29,Calc!$C$6:$AI$6,0))} -> 0.1575
A39: Cargo insurance | B39: {=INDEX(Calc!$C$57:$AI$57,MATCH(Summary!$A$6&"|"&B$29,Calc!$C$6:$AI$6,0))} -> 0.004015385 | C39: {=INDEX(Calc!$C$57:$AI$57,MATCH(Summary!$A$6&"|"&C$29,Calc!$C$6:$AI$6,0))} -> 0.0094171025 | D39: {=INDEX(Calc!$C$57:$AI$57,MATCH(Summary!$A$6&"|"&D$29,Calc!$C$6:$AI$6,0))} -> 0.010696983
A40: Import duties (BCD + SWS + other) | B40: {=INDEX(Calc!$C$60:$AI$60,MATCH(Summary!$A$6&"|"&B$29,Calc!$C$6:$AI$6,0))+INDEX(Calc!$C$61:$AI$61,MATCH(Summary!$A$6&"|"&B$29,Calc!$C$6:$AI$6,0))+INDEX(Calc!$C$62:$AI$62,MATCH(Summary!$A$6&"|"&B$29,Calc!$C$6:$AI$6,0))} -> 0 | C40: {=INDEX(Calc!$C$60:$AI$60,MATCH(Summary!$A$6&"|"&C$29,Calc!$C$6:$AI$6,0))+INDEX(Calc!$C$61:$AI$61,MATCH(Summary!$A$6&"|"&C$29,Calc!$C$6:$AI$6,0))+INDEX(Calc!$C$62:$AI$62,MATCH(Summary!$A$6&"|"&C$29,Calc!$C$6:$AI$6,0))} -> 0.36134464 | D40: {=INDEX(Calc!$C$60:$AI$60,MATCH(Summary!$A$6&"|"&D$29,Calc!$C$6:$AI$6,0))+INDEX(Calc!$C$61:$AI$61,MATCH(Summary!$A$6&"|"&D$29,Calc!$C$6:$AI$6,0))+INDEX(Calc!$C$62:$AI$62,MATCH(Summary!$A$6&"|"&D$29,Calc!$C$6:$AI$6,0))} -> 0.2053622
A41: Clearance and haulage | B41: {=INDEX(Calc!$C$63:$AI$63,MATCH(Summary!$A$6&"|"&B$29,Calc!$C$6:$AI$6,0))+INDEX(Calc!$C$64:$AI$64,MATCH(Summary!$A$6&"|"&B$29,Calc!$C$6:$AI$6,0))} -> 0 | C41: {=INDEX(Calc!$C$63:$AI$63,MATCH(Summary!$A$6&"|"&C$29,Calc!$C$6:$AI$6,0))+INDEX(Calc!$C$64:$AI$64,MATCH(Summary!$A$6&"|"&C$29,Calc!$C$6:$AI$6,0))} -> 0.016639805 | D41: {=INDEX(Calc!$C$63:$AI$63,MATCH(Summary!$A$6&"|"&D$29,Calc!$C$6:$AI$6,0))+INDEX(Calc!$C$64:$AI$64,MATCH(Summary!$A$6&"|"&D$29,Calc!$C$6:$AI$6,0))} -> 0.018435432
A42: Pipeline carrying cost | B42: {=INDEX(Calc!$C$65:$AI$65,MATCH(Summary!$A$6&"|"&B$29,Calc!$C$6:$AI$6,0))} -> 0.002200211 | C42: {=INDEX(Calc!$C$65:$AI$65,MATCH(Summary!$A$6&"|"&C$29,Calc!$C$6:$AI$6,0))} -> 0.014276155 | D42: {=INDEX(Calc!$C$65:$AI$65,MATCH(Summary!$A$6&"|"&D$29,Calc!$C$6:$AI$6,0))} -> 0.012113479
A43: Total landed cost | B43: =SUM(B30:B42) -> 4.0300006 | C43: =SUM(C30:C42) -> 3.6772119 | D43: =SUM(D30:D42) -> 3.9697692
...

Sheet Inputs
A1: Inputs and assumptions
A2: Blue = input you can change. Yellow = key lever. All USD unless stated.
A4: Global parameters
A5: Parameter | B5: Value | C5: Unit | F5: Basis / source
A6: Finished part weight | B6: 28 | C6: g | F6: Assumption: typical smartphone-class machined enclosure
A7: Blank (billet/extrusion) weight | B7: 85 | C7: g | F7: Assumption: ~3:1 buy-to-fly ratio typical for CNC unibody parts
A8: Chip-scrap recovery value (% of LME) | B8: 0.6 | C8: % | F8: Assumption: machining chips resold at a discount to LME
A9: LME aluminium cash price | B9: 3134 | C9: USD/t | F9: Source: AlCircle, LME cash offer USD 3,134.5/t on 6 Oct 2026 (see Sources)
A10: Annual volume per supplier line (base) | B10: 5000000 | C10: units/yr | F10: Assumption: single dedicated line
A11: Cost of capital (annual) | B11: 0.1 | C11: % | F11: Assumption: used for pipeline inventory carrying cost
A12: Tooling amortisation period | B12: 3 | C12: years | F12: Assumption: product life of one enclosure generation
A13: Packed chargeable weight per unit | B13: 0.07 | C13: kg | F13: Assumption: part plus protective packaging
A14: Social Welfare Surcharge (% of BCD) | B14: 0.1 | C14: % | F14: India customs: SWS is 10% of BCD (verify current rate)
A15: Seller markup on freight + insurance under CIF | B15: 0.08 | C15: % | F15: Assumption: seller margin on arranging carriage
A16: Seller markup on duty, clearance and carrying under DDP | B16: 0.06 | C16: % | F16: Assumption: seller margin on carrying duty and clearance risk
A17: Country parameters (delivered to assembly plant near Chennai)
A18: Parameter | B18: Unit | C18: India | D18: China | E18: Vietnam | F18: Basis / source
A19: Imported into India plant? (1 = yes, 0 = local) | B19: flag | C19: 0 | D19: 1 | E19: 1 | F19: Structural: India supplier is local, others ship in
A20: Regional alloy / fabrication premium over LME | B20: USD/t | C20: 520 | D20: 330 | E20: 450 | F20: Assumption: India includes duty on imported primary metal
A21: CNC cycle time | B21: min/unit | C21: 9 | D21: 8 | E21: 8.8 | F21: Assumption: India slightly slower on learning curve
A22: Machine-hour rate (depreciation, power, tooling) | B22: USD/hr | C22: 14 | D22: 11.5 | E22: 12.5 | F22: Assumption: India higher capital cost and import duty on machines
A23: Operators per machine | B23: ratio | C23: 0.25 | D23: 0.25 | E23: 0.25 | F23: Assumption: 1 operator tends 4 machines
A24: Direct labour rate | B24: USD/hr | C24: 3.2 | D24: 6.5 | E24: 3.8 | F24: Assumption: loaded hourly cost, industrial region
A25: Anodising / finishing cost | B25: USD/unit | C25: 0.55 | D25: 0.4 | E25: 0.48 | F25: Assumption
A26: First-pass yield (base) | B26: % | C26: 0.86 | D26: 0.93 | E26: 0.9 | F26: Assumption: India ramp-up yield below mature China line
A27: Tooling and fixtures capex | B27: USD | C27: 1800000 | D27: 1400000 | E27: 1600000 | F27: Assumption
A28: Fixed overhead | B28: USD/yr | C28: 1200000 | D28: 1500000 | E28: 1100000 | F28: Assumption: rent, supervision, QA
A29: Supplier margin on cost | B29: % | C29: 0.09 | D29: 0.08 | E29: 0.09 | F29: Assumption
A30: Sea / road freight rate | B30: USD/kg | C30: 0.12 | D30: 0.45 | E30: 0.55 | F30: Assumption: India = trucking to plant
... A41: Share of incentive passed to buyer | B41: % | C41: 0.5 | D41: 0 | E41: 0 | F41: Assumption: negotiated; the rest stays with the supplier

Sheet Scenarios
A1: Scenario levers
A2: Each row is one scenario. Multipliers: 1.00 = no change. BCD change is in percentage points added to the import duty rate (floored at 0%). Blue cells can be edited.
A4: Scenario | B4: Import duty change (pts) | C4: Freight multiplier | D4: Volume multiplier | E4: Aluminium price multiplier | F4: ECMS pass-through multiplier | G4: India yield change (pts) | H4: What it represents
A5: Base case | B5: 0 | C5: 1 | D5: 1 | E5: 1 | F5: 1 | G5: 0 | H5: Current duty, freight, metal price and incentive terms
A6: Import duty +10 pts | B6: 0.1 | C6: 1 | D6: 1 | E6: 1 | F6: 1 | G6: 0 | H6: India raises BCD on imported enclosures to protect local capacity
A7: Import duty exempt (BCD to 0) | B7: -1 | C7: 1 | D7: 1 | E7: 1 | F7: 1 | G7: 0 | H7: Duty cut to zero on imported parts (e.g. trade deal or exemption)
A8: Freight spike x2.5 | B8: 0 | C8: 2.5 | D8: 1 | E8: 1 | F8: 1 | G8: 0 | H8: Route disruption or air-freight capacity squeeze
A9: Volume -10% | B9: 0 | C9: 1 | D9: 0.9 | E9: 1 | F9: 1 | G9: 0 | H9: Weaker demand; fixed cost spread over fewer units
A10: Volume +10% | B10: 0 | C10: 1 | D10: 1.1 | E10: 1 | F10: 1 | G10: 0 | H10: Stronger demand; better fixed-cost absorption
A11: Aluminium +15% | B11: 0 | C11: 1 | D11: 1 | E11: 1.15 | F11: 1 | G11: 0 | H11: Metal price rally
A12: ECMS delayed (0% pass-through) | B12: 0 | C12: 1 | D12: 1 | E12: 1 | F12: 0 | G12: 0 | H12: Incentive delayed or not passed to the buyer
A13: India yield -4 pts | B13: 0 | C13: 1 | D13: 1 | E13: 1 | F13: 1 | G13: -0.04 | H13: Slower yield ramp at the Indian supplier
A14: Import-shock stack (duty +10, freight x2.5, Al +15%) | B14: 0.1 | C14: 2.5 | D14: 1 | E14: 1.15 | F14: 1 | G14: 0 | H14: Everything goes wrong for importers at once
A15: India-risk stack (vol -10%, ECMS 0%, yield -4 pts) | B15: 0 | C15: 1 | D15: 0.9 | E15: 1 | F15: 0 | G15: -0.04 | H15: Everything goes wrong for the local supplier at once

Sheet Sensitivity
A1: Sensitivity grids and break-even points
A2: India advantage = China imported landed cost minus India local landed cost. Positive (green) = India local is cheaper.
A4: Reference values pulled from Calc (base case)
A5: China: net ex-works price | B5: {=INDEX(Calc!$C$53:$AI$53,MATCH(Summary!$A$6&"|"&Inputs!$D$18,Calc!$C$6:$AI$6,0))} -> 3.1390342
A6: China: cargo insurance | B6: {=INDEX(Calc!$C$57:$AI$57,MATCH(Summary!$A$6&"|"&Inputs!$D$18,Calc!$C$6:$AI$6,0))} -> 0.0094171025
A7: China: international freight (base) | B7: {=INDEX(Calc!$C$56:$AI$56,MATCH(Summary!$A$6&"|"&Inputs!$D$18,Calc!$C$6:$AI$6,0))} -> 0.1365
A8: China: port-to-plant haulage | B8: {=INDEX(Calc!$C$64:$AI$64,MATCH(Summary!$A$6&"|"&Inputs!$D$18,Calc!$C$6:$AI$6,0))} -> 0.0035
A9: China: pipeline carrying cost | B9: {=INDEX(Calc!$C$65:$AI$65,MATCH(Summary!$A$6&"|"&Inputs!$D$18,Calc!$C$6:$AI$6,0))} -> 0.014276155
A10: Social Welfare Surcharge (% of BCD) | B10: =Inputs!$B$14 -> 0.1
A11: China: additional duty rate | B11: {=INDEX(Calc!$C$32:$AI$32,MATCH(Summary!$A$6&"|"&Inputs!$D$18,Calc!$C$6:$AI$6,0))} -> 0
A12: China: clearance rate | B12: {=INDEX(Calc!$C$33:$AI$33,MATCH(Summary!$A$6&"|"&Inputs!$D$18,Calc!$C$6:$AI$6,0))} -> 0.004
A13: China: base BCD rate | B13: {=INDEX(Calc!$C$59:$AI$59,MATCH(Summary!$A$6&"|"&Inputs!$D$18,Calc!$C$6:$AI$6,0))} -> 0.1
A14: India local: landed cost (base) | B14: {=INDEX(Calc!$C$66:$AI$66,MATCH(Summary!$A$6&"|"&Inputs!$C$18,Calc!$C$6:$AI$6,0))} -> 4.0300006
A15: China imported: landed cost (base) | B15: {=INDEX(Calc!$C$66:$AI$66,MATCH(Summary!$A$6&"|"&Inputs!$D$18,Calc!$C$6:$AI$6,0))} -> 3.6772119
A17: Grid A: India advantage (USD/unit) vs import duty rate (rows) and freight multiplier (columns)
A18: BCD on China imports (rows) / Freight multiplier (columns) | B18: 1 | C18: 1.5 | D18: 2 | E18: 2.5 | F18: 3 | G18: 4
A19: 0 | B19: =(($B$5+$B$6+B$18*$B$7)*(1+((1+$B$10)*$A19+$B$11+$B$12))+$B$8+$B$9)-$B$14 -> -0.71413339 | C19: =(($B$5+$B$6+C$18*$B$7)*(1+((1+$B$10)*$A19+$B$11+$B$12))+$B$8+$B$9)-$B$14 -> -0.64561039 | D19: =(($B$5+$B$6+D$18*$B$7)*(1+((1+$B$10)*$A19+$B$11+$B$12))+$B$8+$B$9)-$B$14 -> -0.57708739 | E19: =(($B$5+$B$6+E$18*$B$7)*(1+((1+$B$10)*$A19+$B$11+$B$12))+$B$8+$B$9)-$B$14 -> -0.50856439 | F19: =(($B$5+$B$6+F$18*$B$7)*(1+((1+$B$10)*$A19+$B$11+$B$12))+$B$8+$B$9)-$B$14 -> -0.44004139 | G19: =(($B$5+$B$6+G$18*$B$7)*(1+((1+$B$10)*$A19+$B$11+$B$12))+$B$8+$B$9)-$B$14 -> -0.30299539
A20: 0.05 | B20: =(($B$5+$B$6+B$18*$B$7)*(1+((1+$B$10)*$A20+$B$11+$B$12))+$B$8+$B$9)-$B$14 -> -0.53346107 | C20: =(($B$5+$B$6+C$18*$B$7)*(1+((1+$B$10)*$A20+$B$11+$B$12))+$B$8+$B$9)-$B$14 -> -0.46118432 | D20: =(($B$5+$B$6+D$18*$B$7)*(1+((1+$B$10)*$A20+$B$11+$B$12))+$B$8+$B$9)-$B$14 -> -0.38890757 | E20: =(($B$5+$B$6+E$18*$B$7)*(1+((1+$B$10)*$A20+$B$11+$B$12))+$B$8+$B$9)-$B$14 -> -0.31663082 | F20: =(($B$5+$B$6+F$18*$B$7)*(1+((1+$B$10)*$A20+$B$11+$B$12))+$B$8+$B$9)-$B$14 -> -0.24435407 | G20: =(($B$5+$B$6+G$18*$B$7)*(1+((1+$B$10)*$A20+$B$11+$B$12))+$B$8+$B$9)-$B$14 -> -0.099800573
A21: 0.1 | B21: =(($B$5+$B$6+B$18*$B$7)*(1+((1+$B$10)*$A21+$B$11+$B$12))+$B$8+$B$9)-$B$14 -> -0.35278875 | C21: =(($B$5+$B$6+C$18*$B$7)*(1+((1+$B$10)*$A21+$B$11+$B$12))+$B$8+$B$9)-$B$14 -> -0.27675825 | D21: =(($B$5+$B$6+D$18*$B$7)*(1+((1+$B$10)*$A21+$B$11+$B$12))+$B$8+$B$9)-$B$14 -> -0.20072775 | E21: =(($B$5+$B$6+E$18*$B$7)*(1+((1+$B$10)*$A21+$B$11+$B$12))+$B$8+$B$9)-$B$14 -> -0.12469725 | F21: =(($B$5+$B$6+F$18*$B$7)*(1+((1+$B$10)*$A21+$B$11+$B$12))+$B$8+$B$9)-$B$14 -> -0.048666753 | G21: =(($B$5+$B$6+G$18*$B$7)*(1+((1+$B$10)*$A21+$B$11+$B$12))+$B$8+$B$9)-$B$14 -> 0.10339425
A22: 0.15 | B22: =(($B$5+$B$6+B$18*$B$7)*(1+((1+$B$10)*$A22+$B$11+$B$12))+$B$8+$B$9)-$B$14 -> -0.17211643 | C22: =(($B$5+$B$6+C$18*$B$7)*(1+((1+$B$10)*$A22+$B$11+$B$12))+$B$8+$B$9)-$B$14 -> -0.092332183 | D22: =(($B$5+$B$6+D$18*$B$7)*(1+((1+$B$10)*$A22+$B$11+$B$12))+$B$8+$B$9)-$B$14 -> -0.012547933 | E22: =(($B$5+$B$6+E$18*$B$7)*(1+((1+$B$10)*$A22+$B$11+$B$12))+$B$8+$B$9)-$B$14 -> 0.067236317 | F22: =(($B$5+$B$6+F$18*$B$7)*(1+((1+$B$10)*$A22+$B$11+$B$12))+$B$8+$B$9)-$B$14 -> 0.14702057 | G22: =(($B$5+$B$6+G$18*$B$7)*(1+((1+$B$10)*$A22+$B$11+$B$12))+$B$8+$B$9)-$B$14 -> 0.30658907
A23: 0.2 | B23: =(($B$5+$B$6+B$18*$B$7)*(1+((1+$B$10)*$A23+$B$11+$B$12))+$B$8+$B$9)-$B$14 -> 0.0085558871 | C23: =(($B$5+$B$6+C$18*$B$7)*(1+((1+$B$10)*$A23+$B$11+$B$12))+$B$8+$B$9)-$B$14 -> 0.092093887 | D23: =(($B$5+$B$6+D$18*$B$7)*(1+((1+$B$10)*$A23+$B$11+$B$12))+$B$8+$B$9)-$B$14 -> 0.17563189 | E23: =(($B$5+$B$6+E$18*$B$7)*(1+((1+$B$10)*$A23+$B$11+$B$12))+$B$8+$B$9)-$B$14 -> 0.25916989 | F23: =(($B$5+$B$6+F$18*$B$7)*(1+((1+$B$10)*$A23+$B$11+$B$12))+$B$8+$B$9)-$B$14 -> 0.34270789 | G23: =(($B$5+$B$6+G$18*$B$7)*(1+((1+$B$10)*$A23+$B$11+$B$12))+$B$8+$B$9)-$B$14 -> 0.50978389
A24: 0.25 | B24: =(($B$5+$B$6+B$18*$B$7)*(1+((1+$B$10)*$A24+$B$11+$B$12))+$B$8+$B$9)-$B$14 -> 0.18922821 | C24: =(($B$5+$B$6+C$18*$B$7)*(1+((1+$B$10)*$A24+$B$11+$B$12))+$B$8+$B$9)-$B$14 -> 0.27651996 | D24: =(($B$5+$B$6+D$18*$B$7)*(1+((1+$B$10)*$A24+$B$11+$B$12))+$B$8+$B$9)-$B$14 -> 0.36381171 | E24: =(($B$5+$B$6+E$18*$B$7)*(1+((1+$B$10)*$A24+$B$11+$B$12))+$B$8+$B$9)-$B$14 -> 0.45110346 | F24: =(($B$5+$B$6+F$18*$B$7)*(1+((1+$B$10)*$A24+$B$11+$B$12))+$B$8+$B$9)-$B$14 -> 0.53839521 | G24: =(($B$5+$B$6+G$18*$B$7)*(1+((1+$B$10)*$A24+$B$11+$B$12))+$B$8+$B$9)-$B$14 -> 0.71297871
A25: 0.3 | B25: =(($B$5+$B$6+B$18*$B$7)*(1+((1+$B$10)*$A25+$B$11+$B$12))+$B$8+$B$9)-$B$14 -> 0.36990053 | C25: =(($B$5+$B$6+C$18*$B$7)*(1+((1+$B$10)*$A25+$B$11+$B$12))+$B$8+$B$9)-$B$14 -> 0.46094603 | D25: =(($B$5+$B$6+D$18*$B$7)*(1+((1+$B$10)*$A25+$B$11+$B$12))+$B$8+$B$9)-$B$14 -> 0.55199153 | E25: =(($B$5+$B$6+E$18*$B$7)*(1+((1+$B$10)*$A25+$B$11+$B$12))+$B$8+$B$9)-$B$14 -> 0.64303703 | F25: =(($B$5+$B$6+F$18*$B$7)*(1+((1+$B$10)*$A25+$B$11+$B$12))+$B$8+$B$9)-$B$14 -> 0.73408253 | G25: =(($B$5+$B$6+G$18*$B$7)*(1+((1+$B$10)*$A25+$B$11+$B$12))+$B$8+$B$9)-$B$14 -> 0.91617353
A26: Break-even BCD on China imports at base freight (India local = China) | B26: =(((B14-B8-B9)/(B5+B6+B7)-1)-B11-B12)/(1+B10) -> 0.19763221
A27: Break-even freight multiplier at base BCD (India local = China) | B27: =((B14-B8-B9)/(1+((1+B10)*B13+B11+B12))-(B5+B6))/B7 -> 3.3200476
A28: Check: grid formula at base BCD and 1.0x freight minus Calc (should be 0) | B28: =ROUND((($B$5+$B$6+1*$B$7)*(1+((1+$B$10)*$B$13+$B$11+$B$12))+$B$8+$B$9)-$B$15,6) -> 0
A30: Grid B: India advantage (USD/unit) vs India first-pass yield (rows) and ECMS pass-through to buyer (columns)
A31: India reference values (base case)
A32: India: net material + conversion | B32: {=INDEX(Calc!$C$41:$AI$41,MATCH(Summary!$A$6&"|"&Inputs!$C$18,Calc!$C$6:$AI$6,0))+INDEX(Calc!$C$45:$AI$45,MATCH(Summary!$A$6&"|"&Inputs!$C$18,Calc!$C$6:$AI$6,0))} -> 2.9734072
A33: India: fixed cost per unit | B33: {=INDEX(Calc!$C$48:$AI$48,MATCH(Summary!$A$6&"|"&Inputs!$C$18,Calc!$C$6:$AI$6,0))} -> 0.36
A34: India: supplier margin | B34: {=INDEX(Calc!$C$24:$AI$24,MATCH(Summary!$A$6&"|"&Inputs!$C$18,Calc!$C$6:$AI$6,0))} -> 0.09
A35: India: ECMS incentive rate | B35: {=INDEX(Calc!$C$35:$AI$35,MATCH(Summary!$A$6&"|"&Inputs!$C$18,Calc!$C$6:$AI$6,0))} -> 0.07
A36: India: insurance + carrying factor (on price) | B36: {=INDEX(Calc!$C$30:$AI$30,MATCH(Summary!$A$6&"|"&Inputs!$C$18,Calc!$C$6:$AI$6,0))+Inputs!$B$11*(INDEX(Calc!$C$27:$AI$27,MATCH(Summary!$A$6&"|"&Inputs!$C$18,Calc!$C$6:$AI$6,0))*INDEX(Calc!$C$29:$AI$29,MATCH(Summary!$A$6&"|"&Inputs!$C$18,Calc!$C$6:$AI$6,0))+(1-INDEX(Calc!$C$27:$AI$27,MATCH(Summary!$A$6&"|"&Inputs!$C$18,Calc!$C$6:$AI$6,0)))*INDEX(Calc!$C$28:$AI$28,MATCH(Summary!$A$6&"|"&Inputs!$C$18,Calc!$C$6:$AI$6,0)))/365} -> 0.0015479452
A37: India: international freight (trucking) | B37: {=INDEX(Calc!$C$56:$AI$56,MATCH(Summary!$A$6&"|"&Inputs!$C$18,Calc!$C$6:$AI$6,0))} -> 0.0084
A39: India yield (rows) / ECMS pass-through (columns) | B39: 0 | C39: 0.25 | D39: 0.5 | E39: 0.75 | F39: 1
A40: 0.8 | B40: =$B$15-((($B$32/$A40+$B$33)*(1+$B$34))*(1-$B$35*MIN(1,B$39))*(1+$B$36)+$B$37) -> -0.78173399 | C40: =$B$15-((($B$32/$A40+$B$33)*(1+$B$34))*(1-$B$35*MIN(1,C$39))*(1+$B$36)+$B$37) -> -0.70384944 | D40: =$B$15-((($B$32/$A40+$B$33)*(1+$B$34))*(1-$B$35*MIN(1,D$39))*(1+$B$36)+$B$37) -> -0.62596489 | E40: =$B$15-((($B$32/$A40+$B$33)*(1+$B$34))*(1-$B$35*MIN(1,E$39))*(1+$B$36)+$B$37) -> -0.54808034 | F40: =$B$15-((($B$32/$A40+$B$33)*(1+$B$34))*(1-$B$35*MIN(1,F$39))*(1+$B$36)+$B$37) -> -0.47019578
A41: 0.83 | B41: =$B$15-((($B$32/$A41+$B$33)*(1+$B$34))*(1-$B$35*MIN(1,B$39))*(1+$B$36)+$B$37) -> -0.63507598 | C41: =$B$15-((($B$32/$A41+$B$33)*(1+$B$34))*(1-$B$35*MIN(1,C$39))*(1+$B$36)+$B$37) -> -0.55975794 | D41: =$B$15-((($B$32/$A41+$B$33)*(1+$B$34))*(1-$B$35*MIN(1,D$39))*(1+$B$36)+$B$37) -> -0.4844399 | E41: =$B$15-((($B$32/$A41+$B$33)*(1+$B$34))*(1-$B$35*MIN(1,E$39))*(1+$B$36)+$B$37) -> -0.40912186 | F41: =$B$15-((($B$32/$A41+$B$33)*(1+$B$34))*(1-$B$35*MIN(1,F$39))*(1+$B$36)+$B$37) -> -0.33380383
A42: 0.86 | B42: =$B$15-((($B$32/$A42+$B$33)*(1+$B$34))*(1-$B$35*MIN(1,B$39))*(1+$B$36)+$B$37) -> -0.49864992 | C42: =$B$15-((($B$32/$A42+$B$33)*(1+$B$34))*(1-$B$35*MIN(1,C$39))*(1+$B$36)+$B$37) -> -0.42571933 | D42: =$B$15-((($B$32/$A42+$B$33)*(1+$B$34))*(1-$B$35*MIN(1,D$39))*(1+$B$36)+$B$37) -> -0.35278875 | E42: =$B$15-((($B$32/$A42+$B$33)*(1+$B$34))*(1-$B$35*MIN(1,E$39))*(1+$B$36)+$B$37) -> -0.27985817 | F42: =$B$15-((($B$32/$A42+$B$33)*(1+$B$34))*(1-$B$35*MIN(1,F$39))*(1+$B$36)+$B$37) -> -0.20692759
A43: 0.89 | B43: =$B$15-((($B$32/$A43+$B$33)*(1+$B$34))*(1-$B$35*MIN(1,B$39))*(1+$B$36)+$B$37) -> -0.37142112 | C43: =$B$15-((($B$32/$A43+$B$33)*(1+$B$34))*(1-$B$35*MIN(1,C$39))*(1+$B$36)+$B$37) -> -0.30071704 | D43: =$B$15-((($B$32/$A43+$B$33)*(1+$B$34))*(1-$B$35*MIN(1,D$39))*(1+$B$36)+$B$37) -> -0.23001296 | E43: =$B$15-((($B$32/$A43+$B$33)*(1+$B$34))*(1-$B$35*MIN(1,E$39))*(1+$B$36)+$B$37) -> -0.15930888 | F43: =$B$15-((($B$32/$A43+$B$33)*(1+$B$34))*(1-$B$35*MIN(1,F$39))*(1+$B$36)+$B$37) -> -0.088604807
A44: 0.92 | B44: =$B$15-((($B$32/$A44+$B$33)*(1+$B$34))*(1-$B$35*MIN(1,B$39))*(1+$B$36)+$B$37) -> -0.25248985 | C44: =$B$15-((($B$32/$A44+$B$33)*(1+$B$34))*(1-$B$35*MIN(1,C$39))*(1+$B$36)+$B$37) -> -0.18386707 | D44: =$B$15-((($B$32/$A44+$B$33)*(1+$B$34))*(1-$B$35*MIN(1,D$39))*(1+$B$36)+$B$37) -> -0.11524429 | E44: =$B$15-((($B$32/$A44+$B$33)*(1+$B$34))*(1-$B$35*MIN(1,E$39))*(1+$B$36)+$B$37) -> -0.046621507 | F44: =$B$15-((($B$32/$A44+$B$33)*(1+$B$34))*(1-$B$35*MIN(1,F$39))*(1+$B$36)+$B$37) -> 0.022001273
...

Sheet Incoterms
A1: Incoterms comparison: who pays what for an imported enclosure (USD per unit, base case)
A2: Pick the exporting country in the yellow cell. FOB = buyer arranges carriage. CIF = seller pays freight and insurance to the Indian port. DDP = seller delivers duty paid to the plant.
A3: Exporting country | B3: China
A5: Cost elements and who bears them
A6: Cost element | B6: FOB: Seller | C6: FOB: Buyer | D6: CIF: Seller | E6: CIF: Buyer | F6: DDP: Seller | G6: DDP: Buyer | J6: Base value
A7: Ex-works price (net of any incentive) | B7: =IF("S"="S",$J7,0) -> 3.1390342 | C7: =IF("S"="B",$J7,0) -> 0 | D7: =IF("S"="S",$J7,0) -> 3.1390342 | E7: =IF("S"="B",$J7,0) -> 0 | F7: =IF("S"="S",$J7,0) -> 3.1390342 | G7: =IF("S"="B",$J7,0) -> 0 | J7: {=INDEX(Calc!$C$53:$AI$53,MATCH(Summary!$A$6&"|"&$B$3,Calc!$C$6:$AI$6,0))} -> 3.1390342
A8: International freight | B8: =IF("B"="S",$J8,0) -> 0 | C8: =IF("B"="B",$J8,0) -> 0.1365 | D8: =IF("S"="S",$J8,0) -> 0.1365 | E8: =IF("S"="B",$J8,0) -> 0 | F8: =IF("S"="S",$J8,0) -> 0.1365 | G8: =IF("S"="B",$J8,0) -> 0 | J8: {=INDEX(Calc!$C$56:$AI$56,MATCH(Summary!$A$6&"|"&$B$3,Calc!$C$6:$AI$6,0))} -> 0.1365
A9: Cargo insurance | B9: =IF("B"="S",$J9,0) -> 0 | C9: =IF("B"="B",$J9,0) -> 0.0094171025 | D9: =IF("S"="S",$J9,0) -> 0.0094171025 | E9: =IF("S"="B",$J9,0) -> 0 | F9: =IF("S"="S",$J9,0) -> 0.0094171025 | G9: =IF("S"="B",$J9,0) -> 0 | J9: {=INDEX(Calc!$C$57:$AI$57,MATCH(Summary!$A$6&"|"&$B$3,Calc!$C$6:$AI$6,0))} -> 0.0094171025
A10: Import duties (BCD + SWS + other) | B10: =IF("B"="S",$J10,0) -> 0 | C10: =IF("B"="B",$J10,0) -> 0.36134464 | D10: =IF("B"="S",$J10,0) -> 0 | E10: =IF("B"="B",$J10,0) -> 0.36134464 | F10: =IF("S"="S",$J10,0) -> 0.36134464 | G10: =IF("S"="B",$J10,0) -> 0 | J10: {=INDEX(Calc!$C$60:$AI$60,MATCH(Summary!$A$6&"|"&$B$3,Calc!$C$6:$AI$6,0))+INDEX(Calc!$C$61:$AI$61,MATCH(Summary!$A$6&"|"&$B$3,Calc!$C$6:$AI$6,0))+INDEX(Calc!$C$62:$AI$62,MATCH(Summary!$A$6&"|"&$B$3,Calc!$C$6:$AI$6,0))} -> 0.36134464
A11: Customs clearance and port-to-plant haulage | B11: =IF("B"="S",$J11,0) -> 0 | C11: =IF("B"="B",$J11,0) -> 0.016639805 | D11: =IF("B"="S",$J11,0) -> 0 | E11: =IF("B"="B",$J11,0) -> 0.016639805 | F11: =IF("S"="S",$J11,0) -> 0.016639805 | G11: =IF("S"="B",$J11,0) -> 0 | J11: {=INDEX(Calc!$C$63:$AI$63,MATCH(Summary!$A$6&"|"&$B$3,Calc!$C$6:$AI$6,0))+INDEX(Calc!$C$64:$AI$64,MATCH(Summary!$A$6&"|"&$B$3,Calc!$C$6:$AI$6,0))} -> 0.016639805
A12: Pipeline carrying cost (inventory financing) | B12: =IF("B"="S",$J12,0) -> 0 | C12: =IF("B"="B",$J12,0) -> 0.014276155 | D12: =IF("B"="S",$J12,0) -> 0 | E12: =IF("B"="B",$J12,0) -> 0.014276155 | F12: =IF("S"="S",$J12,0) -> 0.014276155 | G12: =IF("S"="B",$J12,0) -> 0 | J12: {=INDEX(Calc!$C$65:$AI$65,MATCH(Summary!$A$6&"|"&$B$3,Calc!$C$6:$AI$6,0))} -> 0.014276155
A13: Seller subtotal / Buyer subtotal (before markups) | B13: =SUM(B7:B12) -> 3.1390342 | C13: =SUM(C7:C12) -> 0.5381777 | D13: =SUM(D7:D12) -> 3.2849513 | E13: =SUM(E7:E12) -> 0.3922606 | F13: =SUM(F7:F12) -> 3.6772119 | G13: =SUM(G7:G12) -> 0
A14: Seller service markup passed to buyer | B14: 0 | C14: 0 | E14: =Inputs!$B$15*($J$8+$J$9) -> 0.011673368 | G14: =Inputs!$B$15*($J$8+$J$9)+Inputs!$B$16*($J$10+$J$11+$J$12) -> 0.035209004
A16: Total cost to buyer (USD/unit) | B16: FOB | C16: =SUM($J$7:$J$12)+C14 -> 3.6772119 | D16: CIF | E16: =SUM($J$7:$J$12)+E14 -> 3.6888852 | F16: DDP | G16: =SUM($J$7:$J$12)+G14 -> 3.7124209
A17: Premium vs FOB (%) | C17: =C16/$C$16-1 -> 0 | E17: =E16/$C$16-1 -> 0.0031745161 | G17: =G16/$C$16-1 -> 0.0095749186
A18: Check: FOB total equals Calc landed cost (should be 0) | C18: {=ROUND(C16-INDEX(Calc!$C$66:$AI$66,MATCH(Summary!$A$6&"|"&$B$3,Calc!$C$6:$AI$6,0)),6)} -> 0
A20: Risk and control (qualitative)
B21: FOB | D21: CIF | F21: DDP
A22: Risk transfers to buyer at | B22: Loading on vessel/aircraft at origin | D22: Loading on vessel/aircraft at origin | F22: Delivery at the plant
A23: Who books and controls carriage | B23: Buyer | D23: Seller | F23: Seller
A24: Who bears Indian duty-rate change risk | B24: Buyer | D24: Buyer | F24: Seller (until re-priced)
A25: Who handles Indian customs clearance | B25: Buyer | D25: Buyer | F25: Seller
A26: Best fit when | B26: Buyer has scale freight contracts and customs expertise | D26: Seller is better placed to buy freight; buyer keeps duty control | F26: Buyer wants one landed price; accepts a premium for fewer touchpoints

Sheet Calc
A1: Calculation engine: one column per scenario x country (identical formulas in every column)
A2: Do not edit. Inputs come from the Inputs and Scenarios sheets. USD per unit unless stated.
A4: Scenario | C4: =Scenarios!$A$5 -> Base case | D4: =Scenarios!$A$5 -> Base case | E4: =Scenarios!$A$5 -> Base case | F4: =Scenarios!$A$6 -> Import duty +10 pts | G4: =Scenarios!$A$6 -> Import duty +10 pts | H4: =Scenarios!$A$6 -> Import duty +10 pts | I4: =Scenarios!$A$7 -> Import duty exempt (BCD to 0) | J4: =Scenarios!$A$7 -> Import duty exempt (BCD to 0) | K4: =Scenarios!$A$7 -> Import duty exempt (BCD to 0) | L4: =Scenarios!$A$8 -> Freight spike x2.5 | M4: =Scenarios!$A$8 -> Freight spike x2.5 | N4: =Scenarios!$A$8 -> Freight spike x2.5 | O4: =Scenarios!$A$9 -> Volume -10% | P4: =Scenarios!$A$9 -> Volume -10% | Q4: =Scenarios!$A$9 -> Volume -10% | R4: =Scenarios!$A$10 -> Volume +10% | S4: =Scenarios!$A$10 -> Volume +10% | T4: =Scenarios!$A$10 -> Volume +10% | U4: =Scenarios!$A$11 -> Aluminium +15% | V4: =Scenarios!$A$11 -> Aluminium +15% | W4: =Scenarios!$A$11 -> Aluminium +15% | X4: =Scenarios!$A$12 -> ECMS delayed (0% pass-through) | Y4: =Scenarios!$A$12 -> ECMS delayed (0% pass-through) | Z4: =Scenarios!$A$12 -> ECMS delayed (0% pass-through) | AA4: =Scenarios!$A$13 -> India yield -4 pts | AB4: =Scenarios!$A$13 -> India yield -4 pts | AC4: =Scenarios!$A$13 -> India yield -4 pts | AD4: =Scenarios!$A$14 -> Import-shock stack (duty +10, freight x2.5, Al +15%) | AE4: =Scenarios!$A$14 -> Import-shock stack (duty +10, freight x2.5, Al +15%) | AF4: =Scenarios!$A$14 -> Import-shock stack (duty +10, freight x2.5, Al +15%) | AG4: =Scenarios!$A$15 -> India-risk stack (vol -10%, ECMS 0%, yield -4 pts) | AH4: =Scenarios!$A$15 -> India-risk stack (vol -10%, ECMS 0%, yield -4 pts) | AI4: =Scenarios!$A$15 -> India-risk stack (vol -10%, ECMS 0%, yield -4 pts)
A5: Country | C5: =Inputs!$C$18 -> India | D5: =Inputs!$D$18 -> China | E5: =Inputs!$E$18 -> Vietnam | F5: =Inputs!$C$18 -> India | G5: =Inputs!$D$18 -> China | H5: =Inputs!$E$18 -> Vietnam | I5: =Inputs!$C$18 -> India | J5: =Inputs!$D$18 -> China | K5: =Inputs!$E$18 -> Vietnam | L5: =Inputs!$C$18 -> India | M5: =Inputs!$D$18 -> China | N5: =Inputs!$E$18 -> Vietnam | O5: =Inputs!$C$18 -> India | P5: =Inputs!$D$18 -> China | Q5: =Inputs!$E$18 -> Vietnam | R5: =Inputs!$C$18 -> India | S5: =Inputs!$D$18 -> China | T5: =Inputs!$E$18 -> Vietnam | U5: =Inputs!$C$18 -> India | V5: =Inputs!$D$18 -> China | W5: =Inputs!$E$18 -> Vietnam | X5: =Inputs!$C$18 -> India | Y5: =Inputs!$D$18 -> China | Z5: =Inputs!$E$18 -> Vietnam | AA5: =Inputs!$C$18 -> India | AB5: =Inputs!$D$18 -> China | AC5: =Inputs!$E$18 -> Vietnam | AD5: =Inputs!$C$18 -> India | AE5: =Inputs!$D$18 -> China | AF5: =Inputs!$E$18 -> Vietnam | AG5: =Inputs!$C$18 -> India | AH5: =Inputs!$D$18 -> China | AI5: =Inputs!$E$18 -> Vietnam
A6: Lookup key | C6: =C4&"|"&C5 -> Base case|India | D6: =D4&"|"&D5 -> Base case|China | E6: =E4&"|"&E5 -> Base case|Vietnam | F6: =F4&"|"&F5 -> Import duty +10 pts|India | G6: =G4&"|"&G5 -> Import duty +10 pts|China | H6: =H4&"|"&H5 -> Import duty +10 pts|Vietnam | I6: =I4&"|"&I5 -> Import duty exempt (BCD to 0)|India | J6: =J4&"|"&J5 -> Import duty exempt (BCD to 0)|China | ... AI6: =AI4&"|"&AI5 -> India-risk stack (vol -10%, ECMS 0%, yield -4 pts)|Vietnam
A7: Import duty change | B7: pts | C7: {=INDEX(Scenarios!$B$5:$B$15,MATCH(C$4,Scenarios!$A$5:$A$15,0))} -> 0 | D7: {=INDEX(Scenarios!$B$5:$B$15,MATCH(D$4,Scenarios!$A$5:$A$15,0))} -> 0 | E7: {=INDEX(Scenarios!$B$5:$B$15,MATCH(E$4,Scenarios!$A$5:$A$15,0))} -> 0 | F7: {=INDEX(Scenarios!$B$5:$B$15,MATCH(F$4,Scenarios!$A$5:$A$15,0))} -> 0.1 | G7: {=INDEX(Scenarios!$B$5:$B$15,MATCH(G$4,Scenarios!$A$5:$A$15,0))} -> 0.1 | H7: {=INDEX(Scenarios!$B$5:$B$15,MATCH(H$4,Scenarios!$A$5:$A$15,0))} -> 0.1 | I7: {=INDEX(Scenarios!$B$5:$B$15,MATCH(I$4,Scenarios!$A$5:$A$15,0))} -> -1 | J7: {=INDEX(Scenarios!$B$5:$B$15,MATCH(J$4,Scenarios!$A$5:$A$15,0))} -> -1 | ... AI7: {=INDEX(Scenarios!$B$5:$B$15,MATCH(AI$4,Scenarios!$A$5:$A$15,0))} -> 0
A8: Freight multiplier | B8: x | C8: {=INDEX(Scenarios!$C$5:$C$15,MATCH(C$4,Scenarios!$A$5:$A$15,0))} -> 1 | D8: {=INDEX(Scenarios!$C$5:$C$15,MATCH(D$4,Scenarios!$A$5:$A$15,0))} -> 1 | E8: {=INDEX(Scenarios!$C$5:$C$15,MATCH(E$4,Scenarios!$A$5:$A$15,0))} -> 1 | F8: {=INDEX(Scenarios!$C$5:$C$15,MATCH(F$4,Scenarios!$A$5:$A$15,0))} -> 1 | G8: {=INDEX(Scenarios!$C$5:$C$15,MATCH(G$4,Scenarios!$A$5:$A$15,0))} -> 1 | H8: {=INDEX(Scenarios!$C$5:$C$15,MATCH(H$4,Scenarios!$A$5:$A$15,0))} -> 1 | I8: {=INDEX(Scenarios!$C$5:$C$15,MATCH(I$4,Scenarios!$A$5:$A$15,0))} -> 1 | J8: {=INDEX(Scenarios!$C$5:$C$15,MATCH(J$4,Scenarios!$A$5:$A$15,0))} -> 1 | ... AI8: {=INDEX(Scenarios!$C$5:$C$15,MATCH(AI$4,Scenarios!$A$5:$A$15,0))} -> 1
A9: Volume multiplier | B9: x | C9: {=INDEX(Scenarios!$D$5:$D$15,MATCH(C$4,Scenarios!$A$5:$A$15,0))} -> 1 | D9: {=INDEX(Scenarios!$D$5:$D$15,MATCH(D$4,Scenarios!$A$5:$A$15,0))} -> 1 | E9: {=INDEX(Scenarios!$D$5:$D$15,MATCH(E$4,Scenarios!$A$5:$A$15,0))} -> 1 | F9: {=INDEX(Scenarios!$D$5:$D$15,MATCH(F$4,Scenarios!$A$5:$A$15,0))} -> 1 | G9: {=INDEX(Scenarios!$D$5:$D$15,MATCH(G$4,Scenarios!$A$5:$A$15,0))} -> 1 | H9: {=INDEX(Scenarios!$D$5:$D$15,MATCH(H$4,Scenarios!$A$5:$A$15,0))} -> 1 | I9: {=INDEX(Scenarios!$D$5:$D$15,MATCH(I$4,Scenarios!$A$5:$A$15,0))} -> 1 | J9: {=INDEX(Scenarios!$D$5:$D$15,MATCH(J$4,Scenarios!$A$5:$A$15,0))} -> 1 | ... AI9: {=INDEX(Scenarios!$D$5:$D$15,MATCH(AI$4,Scenarios!$A$5:$A$15,0))} -> 0.9
A10: Aluminium price multiplier | B10: x | C10: {=INDEX(Scenarios!$E$5:$E$15,MATCH(C$4,Scenarios!$A$5:$A$15,0))} -> 1 | D10: {=INDEX(Scenarios!$E$5:$E$15,MATCH(D$4,Scenarios!$A$5:$A$15,0))} -> 1 | E10: {=INDEX(Scenarios!$E$5:$E$15,MATCH(E$4,Scenarios!$A$5:$A$15,0))} -> 1 | F10: {=INDEX(Scenarios!$E$5:$E$15,MATCH(F$4,Scenarios!$A$5:$A$15,0))} -> 1 | G10: {=INDEX(Scenarios!$E$5:$E$15,MATCH(G$4,Scenarios!$A$5:$A$15,0))} -> 1 | H10: {=INDEX(Scenarios!$E$5:$E$15,MATCH(H$4,Scenarios!$A$5:$A$15,0))} -> 1 | I10: {=INDEX(Scenarios!$E$5:$E$15,MATCH(I$4,Scenarios!$A$5:$A$15,0))} -> 1 | J10: {=INDEX(Scenarios!$E$5:$E$15,MATCH(J$4,Scenarios!$A$5:$A$15,0))} -> 1 | ... AI10: {=INDEX(Scenarios!$E$5:$E$15,MATCH(AI$4,Scenarios!$A$5:$A$15,0))} -> 1
A11: ECMS pass-through multiplier | B11: x | C11: {=INDEX(Scenarios!$F$5:$F$15,MATCH(C$4,Scenarios!$A$5:$A$15,0))} -> 1 | D11: {=INDEX(Scenarios!$F$5:$F$15,MATCH(D$4,Scenarios!$A$5:$A$15,0))} -> 1 | E11: {=INDEX(Scenarios!$F$5:$F$15,MATCH(E$4,Scenarios!$A$5:$A$15,0))} -> 1 | F11: {=INDEX(Scenarios!$F$5:$F$15,MATCH(F$4,Scenarios!$A$5:$A$15,0))} -> 1 | G11: {=INDEX(Scenarios!$F$5:$F$15,MATCH(G$4,Scenarios!$A$5:$A$15,0))} -> 1 | H11: {=INDEX(Scenarios!$F$5:$F$15,MATCH(H$4,Scenarios!$A$5:$A$15,0))} -> 1 | I11: {=INDEX(Scenarios!$F$5:$F$15,MATCH(I$4,Scenarios!$A$5:$A$15,0))} -> 1 | J11: {=INDEX(Scenarios!$F$5:$F$15,MATCH(J$4,Scenarios!$A$5:$A$15,0))} -> 1 | ... AI11: {=INDEX(Scenarios!$F$5:$F$15,MATCH(AI$4,Scenarios!$A$5:$A$15,0))} -> 0
A12: India yield change | B12: pts | C12: {=INDEX(Scenarios!$G$5:$G$15,MATCH(C$4,Scenarios!$A$5:$A$15,0))} -> 0 | D12: {=INDEX(Scenarios!$G$5:$G$15,MATCH(D$4,Scenarios!$A$5:$A$15,0))} -> 0 | E12: {=INDEX(Scenarios!$G$5:$G$15,MATCH(E$4,Scenarios!$A$5:$A$15,0))} -> 0 | F12: {=INDEX(Scenarios!$G$5:$G$15,MATCH(F$4,Scenarios!$A$5:$A$15,0))} -> 0 | G12: {=INDEX(Scenarios!$G$5:$G$15,MATCH(G$4,Scenarios!$A$5:$A$15,0))} -> 0 | H12: {=INDEX(Scenarios!$G$5:$G$15,MATCH(H$4,Scenarios!$A$5:$A$15,0))} -> 0 | I12: {=INDEX(Scenarios!$G$5:$G$15,MATCH(I$4,Scenarios!$A$5:$A$15,0))} -> 0 | J12: {=INDEX(Scenarios!$G$5:$G$15,MATCH(J$4,Scenarios!$A$5:$A$15,0))} -> 0 | ... AI12: {=INDEX(Scenarios!$G$5:$G$15,MATCH(AI$4,Scenarios!$A$5:$A$15,0))} -> -0.04
A13: COUNTRY INPUTS (looked up from Inputs)
A14: Imported into India plant? (1/0) | B14: flag | C14: {=INDEX(Inputs!$C$19:$E$19,MATCH(C$5,Inputs!$C$18:$E$18,0))} -> 0 | D14: {=INDEX(Inputs!$C$19:$E$19,MATCH(D$5,Inputs!$C$18:$E$18,0))} -> 1 | E14: {=INDEX(Inputs!$C$19:$E$19,MATCH(E$5,Inputs!$C$18:$E$18,0))} -> 1 | F14: {=INDEX(Inputs!$C$19:$E$19,MATCH(F$5,Inputs!$C$18:$E$18,0))} -> 0 | G14: {=INDEX(Inputs!$C$19:$E$19,MATCH(G$5,Inputs!$C$18:$E$18,0))} -> 1 | H14: {=INDEX(Inputs!$C$19:$E$19,MATCH(H$5,Inputs!$C$18:$E$18,0))} -> 1 | I14: {=INDEX(Inputs!$C$19:$E$19,MATCH(I$5,Inputs!$C$18:$E$18,0))} -> 0 | J14: {=INDEX(Inputs!$C$19:$E$19,MATCH(J$5,Inputs!$C$18:$E$18,0))} -> 1 | ... AI14: {=INDEX(Inputs!$C$19:$E$19,MATCH(AI$5,Inputs!$C$18:$E$18,0))} -> 1
A15: Alloy / fabrication premium | B15: USD/t | C15: {=INDEX(Inputs!$C$20:$E$20,MATCH(C$5,Inputs!$C$18:$E$18,0))} -> 520 | D15: {=INDEX(Inputs!$C$20:$E$20,MATCH(D$5,Inputs!$C$18:$E$18,0))} -> 330 | E15: {=INDEX(Inputs!$C$20:$E$20,MATCH(E$5,Inputs!$C$18:$E$18,0))} -> 450 | F15: {=INDEX(Inputs!$C$20:$E$20,MATCH(F$5,Inputs!$C$18:$E$18,0))} -> 520 | G15: {=INDEX(Inputs!$C$20:$E$20,MATCH(G$5,Inputs!$C$18:$E$18,0))} -> 330 | H15: {=INDEX(Inputs!$C$20:$E$20,MATCH(H$5,Inputs!$C$18:$E$18,0))} -> 450 | I15: {=INDEX(Inputs!$C$20:$E$20,MATCH(I$5,Inputs!$C$18:$E$18,0))} -> 520 | J15: {=INDEX(Inputs!$C$20:$E$20,MATCH(J$5,Inputs!$C$18:$E$18,0))} -> 330 | ... AI15: {=INDEX(Inputs!$C$20:$E$20,MATCH(AI$5,Inputs!$C$18:$E$18,0))} -> 450
A16: CNC cycle time | B16: min | C16: {=INDEX(Inputs!$C$21:$E$21,MATCH(C$5,Inputs!$C$18:$E$18,0))} -> 9 | D16: {=INDEX(Inputs!$C$21:$E$21,MATCH(D$5,Inputs!$C$18:$E$18,0))} -> 8 | E16: {=INDEX(Inputs!$C$21:$E$21,MATCH(E$5,Inputs!$C$18:$E$18,0))} -> 8.8 | F16: {=INDEX(Inputs!$C$21:$E$21,MATCH(F$5,Inputs!$C$18:$E$18,0))} -> 9 | G16: {=INDEX(Inputs!$C$21:$E$21,MATCH(G$5,Inputs!$C$18:$E$18,0))} -> 8 | H16: {=INDEX(Inputs!$C$21:$E$21,MATCH(H$5,Inputs!$C$18:$E$18,0))} -> 8.8 | I16: {=INDEX(Inputs!$C$21:$E$21,MATCH(I$5,Inputs!$C$18:$E$18,0))} -> 9 | J16: {=INDEX(Inputs!$C$21:$E$21,MATCH(J$5,Inputs!$C$18:$E$18,0))} -> 8 | ... AI16: {=INDEX(Inputs!$C$21:$E$21,MATCH(AI$5,Inputs!$C$18:$E$18,0))} -> 8.8
A17: Machine-hour rate | B17: USD/hr | C17: {=INDEX(Inputs!$C$22:$E$22,MATCH(C$5,Inputs!$C$18:$E$18,0))} -> 14 | D17: {=INDEX(Inputs!$C$22:$E$22,MATCH(D$5,Inputs!$C$18:$E$18,0))} -> 11.5 | E17: {=INDEX(Inputs!$C$22:$E$22,MATCH(E$5,Inputs!$C$18:$E$18,0))} -> 12.5 | F17: {=INDEX(Inputs!$C$22:$E$22,MATCH(F$5,Inputs!$C$18:$E$18,0))} -> 14 | G17: {=INDEX(Inputs!$C$22:$E$22,MATCH(G$5,Inputs!$C$18:$E$18,0))} -> 11.5 | H17: {=INDEX(Inputs!$C$22:$E$22,MATCH(H$5,Inputs!$C$18:$E$18,0))} -> 12.5 | I17: {=INDEX(Inputs!$C$22:$E$22,MATCH(I$5,Inputs!$C$18:$E$18,0))} -> 14 | J17: {=INDEX(Inputs!$C$22:$E$22,MATCH(J$5,Inputs!$C$18:$E$18,0))} -> 11.5 | ... AI17: {=INDEX(Inputs!$C$22:$E$22,MATCH(AI$5,Inputs!$C$18:$E$18,0))} -> 12.5
A18: Operators per machine | B18: ratio | C18: {=INDEX(Inputs!$C$23:$E$23,MATCH(C$5,Inputs!$C$18:$E$18,0))} -> 0.25 | D18: {=INDEX(Inputs!$C$23:$E$23,MATCH(D$5,Inputs!$C$18:$E$18,0))} -> 0.25 | E18: {=INDEX(Inputs!$C$23:$E$23,MATCH(E$5,Inputs!$C$18:$E$18,0))} -> 0.25 | F18: {=INDEX(Inputs!$C$23:$E$23,MATCH(F$5,Inputs!$C$18:$E$18,0))} -> 0.25 | G18: {=INDEX(Inputs!$C$23:$E$23,MATCH(G$5,Inputs!$C$18:$E$18,0))} -> 0.25 | H18: {=INDEX(Inputs!$C$23:$E$23,MATCH(H$5,Inputs!$C$18:$E$18,0))} -> 0.25 | I18: {=INDEX(Inputs!$C$23:$E$23,MATCH(I$5,Inputs!$C$18:$E$18,0))} -> 0.25 | J18: {=INDEX(Inputs!$C$23:$E$23,MATCH(J$5,Inputs!$C$18:$E$18,0))} -> 0.25 | ... AI18: {=INDEX(Inputs!$C$23:$E$23,MATCH(AI$5,Inputs!$C$18:$E$18,0))} -> 0.25
A19: Direct labour rate | B19: USD/hr | C19: {=INDEX(Inputs!$C$24:$E$24,MATCH(C$5,Inputs!$C$18:$E$18,0))} -> 3.2 | D19: {=INDEX(Inputs!$C$24:$E$24,MATCH(D$5,Inputs!$C$18:$E$18,0))} -> 6.5 | E19: {=INDEX(Inputs!$C$24:$E$24,MATCH(E$5,Inputs!$C$18:$E$18,0))} -> 3.8 | F19: {=INDEX(Inputs!$C$24:$E$24,MATCH(F$5,Inputs!$C$18:$E$18,0))} -> 3.2 | G19: {=INDEX(Inputs!$C$24:$E$24,MATCH(G$5,Inputs!$C$18:$E$18,0))} -> 6.5 | H19: {=INDEX(Inputs!$C$24:$E$24,MATCH(H$5,Inputs!$C$18:$E$18,0))} -> 3.8 | I19: {=INDEX(Inputs!$C$24:$E$24,MATCH(I$5,Inputs!$C$18:$E$18,0))} -> 3.2 | J19: {=INDEX(Inputs!$C$24:$E$24,MATCH(J$5,Inputs!$C$18:$E$18,0))} -> 6.5 | ... AI19: {=INDEX(Inputs!$C$24:$E$24,MATCH(AI$5,Inputs!$C$18:$E$18,0))} -> 3.8
A20: Finishing cost | B20: USD | C20: {=INDEX(Inputs!$C$25:$E$25,MATCH(C$5,Inputs!$C$18:$E$18,0))} -> 0.55 | D20: {=INDEX(Inputs!$C$25:$E$25,MATCH(D$5,Inputs!$C$18:$E$18,0))} -> 0.4 | E20: {=INDEX(Inputs!$C$25:$E$25,MATCH(E$5,Inputs!$C$18:$E$18,0))} -> 0.48 | F20: {=INDEX(Inputs!$C$25:$E$25,MATCH(F$5,Inputs!$C$18:$E$18,0))} -> 0.55 | G20: {=INDEX(Inputs!$C$25:$E$25,MATCH(G$5,Inputs!$C$18:$E$18,0))} -> 0.4 | H20: {=INDEX(Inputs!$C$25:$E$25,MATCH(H$5,Inputs!$C$18:$E$18,0))} -> 0.48 | I20: {=INDEX(Inputs!$C$25:$E$25,MATCH(I$5,Inputs!$C$18:$E$18,0))} -> 0.55 | J20: {=INDEX(Inputs!$C$25:$E$25,MATCH(J$5,Inputs!$C$18:$E$18,0))} -> 0.4 | ... AI20: {=INDEX(Inputs!$C$25:$E$25,MATCH(AI$5,Inputs!$C$18:$E$18,0))} -> 0.48
A21: First-pass yield (base) | B21: % | C21: {=INDEX(Inputs!$C$26:$E$26,MATCH(C$5,Inputs!$C$18:$E$18,0))} -> 0.86 | D21: {=INDEX(Inputs!$C$26:$E$26,MATCH(D$5,Inputs!$C$18:$E$18,0))} -> 0.93 | E21: {=INDEX(Inputs!$C$26:$E$26,MATCH(E$5,Inputs!$C$18:$E$18,0))} -> 0.9 | F21: {=INDEX(Inputs!$C$26:$E$26,MATCH(F$5,Inputs!$C$18:$E$18,0))} -> 0.86 | G21: {=INDEX(Inputs!$C$26:$E$26,MATCH(G$5,Inputs!$C$18:$E$18,0))} -> 0.93 | H21: {=INDEX(Inputs!$C$26:$E$26,MATCH(H$5,Inputs!$C$18:$E$18,0))} -> 0.9 | I21: {=INDEX(Inputs!$C$26:$E$26,MATCH(I$5,Inputs!$C$18:$E$18,0))} -> 0.86 | J21: {=INDEX(Inputs!$C$26:$E$26,MATCH(J$5,Inputs!$C$18:$E$18,0))} -> 0.93 | ... AI21: {=INDEX(Inputs!$C$26:$E$26,MATCH(AI$5,Inputs!$C$18:$E$18,0))} -> 0.9
A22: Tooling capex | B22: USD | C22: {=INDEX(Inputs!$C$27:$E$27,MATCH(C$5,Inputs!$C$18:$E$18,0))} -> 1800000 | D22: {=INDEX(Inputs!$C$27:$E$27,MATCH(D$5,Inputs!$C$18:$E$18,0))} -> 1400000 | E22: {=INDEX(Inputs!$C$27:$E$27,MATCH(E$5,Inputs!$C$18:$E$18,0))} -> 1600000 | F22: {=INDEX(Inputs!$C$27:$E$27,MATCH(F$5,Inputs!$C$18:$E$18,0))} -> 1800000 | G22: {=INDEX(Inputs!$C$27:$E$27,MATCH(G$5,Inputs!$C$18:$E$18,0))} -> 1400000 | H22: {=INDEX(Inputs!$C$27:$E$27,MATCH(H$5,Inputs!$C$18:$E$18,0))} -> 1600000 | I22: {=INDEX(Inputs!$C$27:$E$27,MATCH(I$5,Inputs!$C$18:$E$18,0))} -> 1800000 | J22: {=INDEX(Inputs!$C$27:$E$27,MATCH(J$5,Inputs!$C$18:$E$18,0))} -> 1400000 | ... AI22: {=INDEX(Inputs!$C$27:$E$27,MATCH(AI$5,Inputs!$C$18:$E$18,0))} -> 1600000
A23: Fixed overhead | B23: USD/yr | C23: {=INDEX(Inputs!$C$28:$E$28,MATCH(C$5,Inputs!$C$18:$E$18,0))} -> 1200000 | D23: {=INDEX(Inputs!$C$28:$E$28,MATCH(D$5,Inputs!$C$18:$E$18,0))} -> 1500000 | E23: {=INDEX(Inputs!$C$28:$E$28,MATCH(E$5,Inputs!$C$18:$E$18,0))} -> 1100000 | F23: {=INDEX(Inputs!$C$28:$E$28,MATCH(F$5,Inputs!$C$18:$E$18,0))} -> 1200000 | G23: {=INDEX(Inputs!$C$28:$E$28,MATCH(G$5,Inputs!$C$18:$E$18,0))} -> 1500000 | H23: {=INDEX(Inputs!$C$28:$E$28,MATCH(H$5,Inputs!$C$18:$E$18,0))} -> 1100000 | I23: {=INDEX(Inputs!$C$28:$E$28,MATCH(I$5,Inputs!$C$18:$E$18,0))} -> 1200000 | J23: {=INDEX(Inputs!$C$28:$E$28,MATCH(J$5,Inputs!$C$18:$E$18,0))} -> 1500000 | ... AI23: {=INDEX(Inputs!$C$28:$E$28,MATCH(AI$5,Inputs!$C$18:$E$18,0))} -> 1100000
A24: Supplier margin | B24: % | C24: {=INDEX(Inputs!$C$29:$E$29,MATCH(C$5,Inputs!$C$18:$E$18,0))} -> 0.09 | D24: {=INDEX(Inputs!$C$29:$E$29,MATCH(D$5,Inputs!$C$18:$E$18,0))} -> 0.08 | E24: {=INDEX(Inputs!$C$29:$E$29,MATCH(E$5,Inputs!$C$18:$E$18,0))} -> 0.09 | F24: {=INDEX(Inputs!$C$29:$E$29,MATCH(F$5,Inputs!$C$18:$E$18,0))} -> 0.09 | G24: {=INDEX(Inputs!$C$29:$E$29,MATCH(G$5,Inputs!$C$18:$E$18,0))} -> 0.08 | H24: {=INDEX(Inputs!$C$29:$E$29,MATCH(H$5,Inputs!$C$18:$E$18,0))} -> 0.09 | I24: {=INDEX(Inputs!$C$29:$E$29,MATCH(I$5,Inputs!$C$18:$E$18,0))} -> 0.09 | J24: {=INDEX(Inputs!$C$29:$E$29,MATCH(J$5,Inputs!$C$18:$E$18,0))} -> 0.08 | ... AI24: {=INDEX(Inputs!$C$29:$E$29,MATCH(AI$5,Inputs!$C$18:$E$18,0))} -> 0.09
A25: Sea / road rate | B25: USD/kg | C25: {=INDEX(Inputs!$C$30:$E$30,MATCH(C$5,Inputs!$C$18:$E$18,0))} -> 0.12 | D25: {=INDEX(Inputs!$C$30:$E$30,MATCH(D$5,Inputs!$C$18:$E$18,0))} -> 0.45 | E25: {=INDEX(Inputs!$C$30:$E$30,MATCH(E$5,Inputs!$C$18:$E$18,0))} -> 0.55 | F25: {=INDEX(Inputs!$C$30:$E$30,MATCH(F$5,Inputs!$C$18:$E$18,0))} -> 0.12 | G25: {=INDEX(Inputs!$C$30:$E$30,MATCH(G$5,Inputs!$C$18:$E$18,0))} -> 0.45 | H25: {=INDEX(Inputs!$C$30:$E$30,MATCH(H$5,Inputs!$C$18:$E$18,0))} -> 0.55 | I25: {=INDEX(Inputs!$C$30:$E$30,MATCH(I$5,Inputs!$C$18:$E$18,0))} -> 0.12 | J25: {=INDEX(Inputs!$C$30:$E$30,MATCH(J$5,Inputs!$C$18:$E$18,0))} -> 0.45 | ... AI25: {=INDEX(Inputs!$C$30:$E$30,MATCH(AI$5,Inputs!$C$18:$E$18,0))} -> 0.55
A26: Air rate | B26: USD/kg | C26: {=INDEX(Inputs!$C$31:$E$31,MATCH(C$5,Inputs!$C$18:$E$18,0))} -> 0 | D26: {=INDEX(Inputs!$C$31:$E$31,MATCH(D$5,Inputs!$C$18:$E$18,0))} -> 4.2 | E26: {=INDEX(Inputs!$C$31:$E$31,MATCH(E$5,Inputs!$C$18:$E$18,0))} -> 4.8 | F26: {=INDEX(Inputs!$C$31:$E$31,MATCH(F$5,Inputs!$C$18:$E$18,0))} -> 0 | G26: {=INDEX(Inputs!$C$31:$E$31,MATCH(G$5,Inputs!$C$18:$E$18,0))} -> 4.2 | H26: {=INDEX(Inputs!$C$31:$E$31,MATCH(H$5,Inputs!$C$18:$E$18,0))} -> 4.8 | I26: {=INDEX(Inputs!$C$31:$E$31,MATCH(I$5,Inputs!$C$18:$E$18,0))} -> 0 | J26: {=INDEX(Inputs!$C$31:$E$31,MATCH(J$5,Inputs!$C$18:$E$18,0))} -> 4.2 | ... AI26: {=INDEX(Inputs!$C$31:$E$31,MATCH(AI$5,Inputs!$C$18:$E$18,0))} -> 4.8
A27: Air share | B27: % | C27: {=INDEX(Inputs!$C$32:$E$32,MATCH(C$5,Inputs!$C$18:$E$18,0))} -> 0 | D27: {=INDEX(Inputs!$C$32:$E$32,MATCH(D$5,Inputs!$C$18:$E$18,0))} -> 0.4 | E27: {=INDEX(Inputs!$C$32:$E$32,MATCH(E$5,Inputs!$C$18:$E$18,0))} -> 0.4 | F27: {=INDEX(Inputs!$C$32:$E$32,MATCH(F$5,Inputs!$C$18:$E$18,0))} -> 0 | G27: {=INDEX(Inputs!$C$32:$E$32,MATCH(G$5,Inputs!$C$18:$E$18,0))} -> 0.4 | H27: {=INDEX(Inputs!$C$32:$E$32,MATCH(H$5,Inputs!$C$18:$E$18,0))} -> 0.4 | I27: {=INDEX(Inputs!$C$32:$E$32,MATCH(I$5,Inputs!$C$18:$E$18,0))} -> 0 | J27: {=INDEX(Inputs!$C$32:$E$32,MATCH(J$5,Inputs!$C$18:$E$18,0))} -> 0.4 | ... AI27: {=INDEX(Inputs!$C$32:$E$32,MATCH(AI$5,Inputs!$C$18:$E$18,0))} -> 0.4
A28: Transit days sea / road | B28: days | C28: {=INDEX(Inputs!$C$33:$E$33,MATCH(C$5,Inputs!$C$18:$E$18,0))} -> 2 | D28: {=INDEX(Inputs!$C$33:$E$33,MATCH(D$5,Inputs!$C$18:$E$18,0))} -> 25 | E28: {=INDEX(Inputs!$C$33:$E$33,MATCH(E$5,Inputs!$C$18:$E$18,0))} -> 18 | F28: {=INDEX(Inputs!$C$33:$E$33,MATCH(F$5,Inputs!$C$18:$E$18,0))} -> 2 | G28: {=INDEX(Inputs!$C$33:$E$33,MATCH(G$5,Inputs!$C$18:$E$18,0))} -> 25 | H28: {=INDEX(Inputs!$C$33:$E$33,MATCH(H$5,Inputs!$C$18:$E$18,0))} -> 18 | I28: {=INDEX(Inputs!$C$33:$E$33,MATCH(I$5,Inputs!$C$18:$E$18,0))} -> 2 | J28: {=INDEX(Inputs!$C$33:$E$33,MATCH(J$5,Inputs!$C$18:$E$18,0))} -> 25 | ... AI28: {=INDEX(Inputs!$C$33:$E$33,MATCH(AI$5,Inputs!$C$18:$E$18,0))} -> 18
A29: Transit days air | B29: days | C29: {=INDEX(Inputs!$C$34:$E$34,MATCH(C$5,Inputs!$C$18:$E$18,0))} -> 2 | D29: {=INDEX(Inputs!$C$34:$E$34,MATCH(D$5,Inputs!$C$18:$E$18,0))} -> 4 | E29: {=INDEX(Inputs!$C$34:$E$34,MATCH(E$5,Inputs!$C$18:$E$18,0))} -> 4 | F29: {=INDEX(Inputs!$C$34:$E$34,MATCH(F$5,Inputs!$C$18:$E$18,0))} -> 2 | G29: {=INDEX(Inputs!$C$34:$E$34,MATCH(G$5,Inputs!$C$18:$E$18,0))} -> 4 | H29: {=INDEX(Inputs!$C$34:$E$34,MATCH(H$5,Inputs!$C$18:$E$18,0))} -> 4 | I29: {=INDEX(Inputs!$C$34:$E$34,MATCH(I$5,Inputs!$C$18:$E$18,0))} -> 2 | J29: {=INDEX(Inputs!$C$34:$E$34,MATCH(J$5,Inputs!$C$18:$E$18,0))} -> 4 | ... AI29: {=INDEX(Inputs!$C$34:$E$34,MATCH(AI$5,Inputs!$C$18:$E$18,0))} -> 4
A30: Cargo insurance rate | B30: % | C30: {=INDEX(Inputs!$C$35:$E$35,MATCH(C$5,Inputs!$C$18:$E$18,0))} -> 0.001 | D30: {=INDEX(Inputs!$C$35:$E$35,MATCH(D$5,Inputs!$C$18:$E$18,0))} -> 0.003 | E30: {=INDEX(Inputs!$C$35:$E$35,MATCH(E$5,Inputs!$C$18:$E$18,0))} -> 0.003 | F30: {=INDEX(Inputs!$C$35:$E$35,MATCH(F$5,Inputs!$C$18:$E$18,0))} -> 0.001 | G30: {=INDEX(Inputs!$C$35:$E$35,MATCH(G$5,Inputs!$C$18:$E$18,0))} -> 0.003 | H30: {=INDEX(Inputs!$C$35:$E$35,MATCH(H$5,Inputs!$C$18:$E$18,0))} -> 0.003 | I30: {=INDEX(Inputs!$C$35:$E$35,MATCH(I$5,Inputs!$C$18:$E$18,0))} -> 0.001 | J30: {=INDEX(Inputs!$C$35:$E$35,MATCH(J$5,Inputs!$C$18:$E$18,0))} -> 0.003 | ... AI30: {=INDEX(Inputs!$C$35:$E$35,MATCH(AI$5,Inputs!$C$18:$E$18,0))} -> 0.003
A31: BCD base rate | B31: % | C31: {=INDEX(Inputs!$C$36:$E$36,MATCH(C$5,Inputs!$C$18:$E$18,0))} -> 0 | D31: {=INDEX(Inputs!$C$36:$E$36,MATCH(D$5,Inputs!$C$18:$E$18,0))} -> 0.1 | E31: {=INDEX(Inputs!$C$36:$E$36,MATCH(E$5,Inputs!$C$18:$E$18,0))} -> 0.05 | F31: {=INDEX(Inputs!$C$36:$E$36,MATCH(F$5,Inputs!$C$18:$E$18,0))} -> 0 | G31: {=INDEX(Inputs!$C$36:$E$36,MATCH(G$5,Inputs!$C$18:$E$18,0))} -> 0.1 | H31: {=INDEX(Inputs!$C$36:$E$36,MATCH(H$5,Inputs!$C$18:$E$18,0))} -> 0.05 | I31: {=INDEX(Inputs!$C$36:$E$36,MATCH(I$5,Inputs!$C$18:$E$18,0))} -> 0 | J31: {=INDEX(Inputs!$C$36:$E$36,MATCH(J$5,Inputs!$C$18:$E$18,0))} -> 0.1 | ... AI31: {=INDEX(Inputs!$C$36:$E$36,MATCH(AI$5,Inputs!$C$18:$E$18,0))} -> 0.05
A32: Additional duty rate | B32: % | C32: {=INDEX(Inputs!$C$37:$E$37,MATCH(C$5,Inputs!$C$18:$E$18,0))} -> 0 | D32: {=INDEX(Inputs!$C$37:$E$37,MATCH(D$5,Inputs!$C$18:$E$18,0))} -> 0 | E32: {=INDEX(Inputs!$C$37:$E$37,MATCH(E$5,Inputs!$C$18:$E$18,0))} -> 0 | F32: {=INDEX(Inputs!$C$37:$E$37,MATCH(F$5,Inputs!$C$18:$E$18,0))} -> 0 | G32: {=INDEX(Inputs!$C$37:$E$37,MATCH(G$5,Inputs!$C$18:$E$18,0))} -> 0 | H32: {=INDEX(Inputs!$C$37:$E$37,MATCH(H$5,Inputs!$C$18:$E$18,0))} -> 0 | I32: {=INDEX(Inputs!$C$37:$E$37,MATCH(I$5,Inputs!$C$18:$E$18,0))} -> 0 | J32: {=INDEX(Inputs!$C$37:$E$37,MATCH(J$5,Inputs!$C$18:$E$18,0))} -> 0 | ... AI32: {=INDEX(Inputs!$C$37:$E$37,MATCH(AI$5,Inputs!$C$18:$E$18,0))} -> 0
A33: Clearance rate | B33: % | C33: {=INDEX(Inputs!$C$38:$E$38,MATCH(C$5,Inputs!$C$18:$E$18,0))} -> 0 | D33: {=INDEX(Inputs!$C$38:$E$38,MATCH(D$5,Inputs!$C$18:$E$18,0))} -> 0.004 | E33: {=INDEX(Inputs!$C$38:$E$38,MATCH(E$5,Inputs!$C$18:$E$18,0))} -> 0.004 | F33: {=INDEX(Inputs!$C$38:$E$38,MATCH(F$5,Inputs!$C$18:$E$18,0))} -> 0 | G33: {=INDEX(Inputs!$C$38:$E$38,MATCH(G$5,Inputs!$C$18:$E$18,0))} -> 0.004 | H33: {=INDEX(Inputs!$C$38:$E$38,MATCH(H$5,Inputs!$C$18:$E$18,0))} -> 0.004 | I33: {=INDEX(Inputs!$C$38:$E$38,MATCH(I$5,Inputs!$C$18:$E$18,0))} -> 0 | J33: {=INDEX(Inputs!$C$38:$E$38,MATCH(J$5,Inputs!$C$18:$E$18,0))} -> 0.004 | ... AI33: {=INDEX(Inputs!$C$38:$E$38,MATCH(AI$5,Inputs!$C$18:$E$18,0))} -> 0.004
A34: Haulage | B34: USD/kg | C34: {=INDEX(Inputs!$C$39:$E$39,MATCH(C$5,Inputs!$C$18:$E$18,0))} -> 0 | D34: {=INDEX(Inputs!$C$39:$E$39,MATCH(D$5,Inputs!$C$18:$E$18,0))} -> 0.05 | E34: {=INDEX(Inputs!$C$39:$E$39,MATCH(E$5,Inputs!$C$18:$E$18,0))} -> 0.05 | F34: {=INDEX(Inputs!$C$39:$E$39,MATCH(F$5,Inputs!$C$18:$E$18,0))} -> 0 | G34: {=INDEX(Inputs!$C$39:$E$39,MATCH(G$5,Inputs!$C$18:$E$18,0))} -> 0.05 | H34: {=INDEX(Inputs!$C$39:$E$39,MATCH(H$5,Inputs!$C$18:$E$18,0))} -> 0.05 | I34: {=INDEX(Inputs!$C$39:$E$39,MATCH(I$5,Inputs!$C$18:$E$18,0))} -> 0 | J34: {=INDEX(Inputs!$C$39:$E$39,MATCH(J$5,Inputs!$C$18:$E$18,0))} -> 0.05 | ... AI34: {=INDEX(Inputs!$C$39:$E$39,MATCH(AI$5,Inputs!$C$18:$E$18,0))} -> 0.05
A35: ECMS incentive rate | B35: % | C35: {=INDEX(Inputs!$C$40:$E$40,MATCH(C$5,Inputs!$C$18:$E$18,0))} -> 0.07 | D35: {=INDEX(Inputs!$C$40:$E$40,MATCH(D$5,Inputs!$C$18:$E$18,0))} -> 0 | E35: {=INDEX(Inputs!$C$40:$E$40,MATCH(E$5,Inputs!$C$18:$E$18,0))} -> 0 | F35: {=INDEX(Inputs!$C$40:$E$40,MATCH(F$5,Inputs!$C$18:$E$18,0))} -> 0.07 | G35: {=INDEX(Inputs!$C$40:$E$40,MATCH(G$5,Inputs!$C$18:$E$18,0))} -> 0 | H35: {=INDEX(Inputs!$C$40:$E$40,MATCH(H$5,Inputs!$C$18:$E$18,0))} -> 0 | I35: {=INDEX(Inputs!$C$40:$E$40,MATCH(I$5,Inputs!$C$18:$E$18,0))} -> 0.07 | J35: {=INDEX(Inputs!$C$40:$E$40,MATCH(J$5,Inputs!$C$18:$E$18,0))} -> 0 | ... AI35: {=INDEX(Inputs!$C$40:$E$40,MATCH(AI$5,Inputs!$C$18:$E$18,0))} -> 0
A36: ECMS pass-through (base) | B36: % | C36: {=INDEX(Inputs!$C$41:$E$41,MATCH(C$5,Inputs!$C$18:$E$18,0))} -> 0.5 | D36: {=INDEX(Inputs!$C$41:$E$41,MATCH(D$5,Inputs!$C$18:$E$18,0))} -> 0 | E36: {=INDEX(Inputs!$C$41:$E$41,MATCH(E$5,Inputs!$C$18:$E$18,0))} -> 0 | F36: {=INDEX(Inputs!$C$41:$E$41,MATCH(F$5,Inputs!$C$18:$E$18,0))} -> 0.5 | G36: {=INDEX(Inputs!$C$41:$E$41,MATCH(G$5,Inputs!$C$18:$E$18,0))} -> 0 | H36: {=INDEX(Inputs!$C$41:$E$41,MATCH(H$5,Inputs!$C$18:$E$18,0))} -> 0 | I36: {=INDEX(Inputs!$C$41:$E$41,MATCH(I$5,Inputs!$C$18:$E$18,0))} -> 0.5 | J36: {=INDEX(Inputs!$C$41:$E$41,MATCH(J$5,Inputs!$C$18:$E$18,0))} -> 0 | ... AI36: {=INDEX(Inputs!$C$41:$E$41,MATCH(AI$5,Inputs!$C$18:$E$18,0))} -> 0
A37: COST BUILD-UP (USD per unit)
A38: Aluminium price incl. premium | B38: USD/kg | C38: =(Inputs!$B$9*C$10+C15)/1000 -> 3.654 | D38: =(Inputs!$B$9*D$10+D15)/1000 -> 3.464 | E38: =(Inputs!$B$9*E$10+E15)/1000 -> 3.584 | F38: =(Inputs!$B$9*F$10+F15)/1000 -> 3.654 | G38: =(Inputs!$B$9*G$10+G15)/1000 -> 3.464 | H38: =(Inputs!$B$9*H$10+H15)/1000 -> 3.584 | I38: =(Inputs!$B$9*I$10+I15)/1000 -> 3.654 | J38: =(Inputs!$B$9*J$10+J15)/1000 -> 3.464 | ... AI38: =(Inputs!$B$9*AI$10+AI15)/1000 -> 3.584
A39: Gross material | B39: USD | C39: =Inputs!$B$7/1000*C38 -> 0.31059 | D39: =Inputs!$B$7/1000*D38 -> 0.29444 | E39: =Inputs!$B$7/1000*E38 -> 0.30464 | F39: =Inputs!$B$7/1000*F38 -> 0.31059 | G39: =Inputs!$B$7/1000*G38 -> 0.29444 | H39: =Inputs!$B$7/1000*H38 -> 0.30464 | I39: =Inputs!$B$7/1000*I38 -> 0.31059 | J39: =Inputs!$B$7/1000*J38 -> 0.29444 | ... AI39: =Inputs!$B$7/1000*AI38 -> 0.30464
A40: Chip-scrap credit | B40: USD | C40: =-(Inputs!$B$7-Inputs!$B$6)/1000*(Inputs!$B$9*C$10/1000)*Inputs!$B$8 -> -0.1071828 | D40: =-(Inputs!$B$7-Inputs!$B$6)/1000*(Inputs!$B$9*D$10/1000)*Inputs!$B$8 -> -0.1071828 | E40: =-(Inputs!$B$7-Inputs!$B$6)/1000*(Inputs!$B$9*E$10/1000)*Inputs!$B$8 -> -0.1071828 | F40: =-(Inputs!$B$7-Inputs!$B$6)/1000*(Inputs!$B$9*F$10/1000)*Inputs!$B$8 -> -0.1071828 | G40: =-(Inputs!$B$7-Inputs!$B$6)/1000*(Inputs!$B$9*G$10/1000)*Inputs!$B$8 -> -0.1071828 | H40: =-(Inputs!$B$7-Inputs!$B$6)/1000*(Inputs!$B$9*H$10/1000)*Inputs!$B$8 -> -0.1071828 | I40: =-(Inputs!$B$7-Inputs!$B$6)/1000*(Inputs!$B$9*I$10/1000)*Inputs!$B$8 -> -0.1071828 | J40: =-(Inputs!$B$7-Inputs!$B$6)/1000*(Inputs!$B$9*J$10/1000)*Inputs!$B$8 -> -0.1071828 | ... AI40: =-(Inputs!$B$7-Inputs!$B$6)/1000*(Inputs!$B$9*AI$10/1000)*Inputs!$B$8 -> -0.1071828
A41: Net material | B41: USD | C41: =C39+C40 -> 0.2034072 | D41: =D39+D40 -> 0.1872572 | E41: =E39+E40 -> 0.1974572 | F41: =F39+F40 -> 0.2034072 | G41: =G39+G40 -> 0.1872572 | H41: =H39+H40 -> 0.1974572 | I41: =I39+I40 -> 0.2034072 | J41: =J39+J40 -> 0.1872572 | ... AI41: =AI39+AI40 -> 0.1974572
...

Sheet Sources
A1: What is sourced and what is assumed
A2: Retrieved 22 Oct 2026. Verify rates against the primary notification before relying on them.
